<?xml version="1.0" encoding="utf-8"?>
<!-- This URDF was automatically created by SolidWorks to URDF Exporter! Originally created by Stephen Brawner (brawner@gmail.com) 
     Commit Version: 1.6.0-4-g7f85cfe  Build Version: 1.6.7995.38578
     For more information, please see http://wiki.ros.org/sw_urdf_exporter -->
<robot
  name="car_robot">
  <link
    name="base_link">
    <inertial>
      <origin
        xyz="5.9003E-18 3.1919E-16 0.38718"
        rpy="0 0 0" />
      <mass
        value="543.54" />
      <inertia
        ixx="93.813"
        ixy="-7.52E-15"
        ixz="-1.8725E-15"
        iyy="40.103"
        iyz="8.6221E-15"
        izz="106.33" />
    </inertial>
    <visual>
      <origin
        xyz="0 0 0"
        rpy="0 0 0" />
      <geometry>
        <mesh
          filename="meshes/base_link.STL" />
      </geometry>
      <material
        name="">
        <color
          rgba="0 1 0 1"/>
      </material>
    </visual>
    <collision>
      <origin
        xyz="0 0 0"
        rpy="0 0 0" />
      <geometry>
        <mesh
          filename="meshes/base_link.STL" />
      </geometry>
    </collision>
  </link>
  <link
    name="wheel1">
    <inertial>
      <origin
        xyz="2.2204E-16 -1.1102E-16 -3.0961E-05"
        rpy="0 0 0" />
      <mass
        value="2.07" />
      <inertia
        ixx="0.013431"
        ixy="6.0615E-18"
        ixz="-1.8962E-19"
        iyy="0.013431"
        iyz="-4.1158E-19"
        izz="0.025767" />
    </inertial>
    <visual>
      <origin
        xyz="0 0 0"
        rpy="0 0 0" />
      <geometry>
        <mesh
          filename="meshes/wheel1.STL" />
      </geometry>
      <material
        name="">
        <color
          rgba="1 1 1 1" />
      </material>
    </visual>
    <collision>
      <origin
        xyz="0 0 0"
        rpy="0 0 0" />
      <surface>
      <friction>
          <ode>
            <mu>2.0</mu>
            <mu2>2.0</mu2>
          </ode>
        </friction>
      </surface>
      <geometry>
        <mesh
          filename="meshes/wheel1.STL" />
      </geometry>
    </collision>
  </link>
  <joint
    name="joint1"
    type="revolute">
    <origin
      xyz="0.361 -0.56 0.14"
      rpy="-1.5708 0 -1.5708" />
    <parent
      link="base_link" />
    <child
      link="wheel1" />
    <axis
      xyz="0 0 -1"/>
    <limit
      lower="-1.79769e+308"
      upper="1.79769e+308"
      effort="10"
      velocity="10" />
  </joint>
  <link
    name="wheel2">
    <inertial>
      <origin
        xyz="3.586E-14 4.9849E-14 -3.0961E-05"
        rpy="0 0 0" />
      <mass
        value="2.07" />
      <inertia
        ixx="0.013431"
        ixy="-9.5721E-18"
        ixz="-1.4338E-17"
        iyy="0.013431"
        iyz="-2.4596E-17"
        izz="0.025767" />
    </inertial>
    <visual>
      <origin
        xyz="0 0 0"
        rpy="0 0 0" />
      <geometry>
        <mesh
          filename="meshes/wheel2.STL" />
      </geometry>
      <material
        name="">
        <color
          rgba="1 1 1 1" />
      </material>
    </visual>
    <collision>
      <origin
        xyz="0 0 0"
        rpy="0 0 0" />
      <surface>
        <friction>
          <ode>
            <mu>2.0</mu>
            <mu2>2.0</mu2>
          </ode>
        </friction>
      </surface>
      <geometry>
        <mesh
          filename="meshes/wheel2.STL" />
      </geometry>
    </collision>
  </link>
  <joint
    name="joint2"
    type="revolute">
    <origin
      xyz="0.361 0.56 0.14"
      rpy="-1.5708 0 -1.5708" />
    <parent
      link="base_link" />
    <child
      link="wheel2" />
    <axis
      xyz="0 0 1" />
    <limit
      lower="-1.79769e+308"
      upper="1.79769e+308"
      effort="10"
      velocity="10"/>
  </joint>
  <link
    name="wheel3">
    <inertial>
      <origin
        xyz="-1.1102E-16 -1.1102E-16 -3.0961E-05"
        rpy="0 0 0" />
      <mass
        value="2.07" />
      <inertia
        ixx="0.013431"
        ixy="-7.5481E-18"
        ixz="1.0785E-18"
        iyy="0.013431"
        iyz="-3.2925E-19"
        izz="0.025767" />
    </inertial>
    <visual>
      <origin
        xyz="0 0 0"
        rpy="0 0 0" />
      <geometry>
        <mesh
          filename="meshes/wheel3.STL" />
      </geometry>
      <material
        name="">
        <color
          rgba="1 1 1 1" />
      </material>
    </visual>
    <collision>
      <origin
        xyz="0 0 0"
        rpy="0 0 0" />
      <surface>
        <friction>
          <ode>
            <mu>2.0</mu>
            <mu2>2.0</mu2>
          </ode>
        </friction>
      </surface>
      <geometry>
        <mesh
          filename="meshes/wheel3.STL" />
      </geometry>
    </collision>
  </link>
  <joint
    name="joint3"
    type="revolute">
    <origin
      xyz="-0.361 0.56 0.14"
      rpy="1.5708 0 -1.5708" />
    <parent
      link="base_link" />
    <child
      link="wheel3" />
    <axis
      xyz="0 0 -1"/>
    <limit
      lower="-1.79769e+308"
      upper="1.79769e+308"
      effort="10"
      velocity="10"/>
  </joint>
  <link
    name="wheel4">
    <inertial>
      <origin
        xyz="5.4179E-14 -5.0182E-14 -3.0961E-05"
        rpy="0 0 0" />
      <mass
        value="2.07" />
      <inertia
        ixx="0.013431"
        ixy="2.0109E-18"
        ixz="-1.1238E-17"
        iyy="0.013431"
        iyz="2.7609E-17"
        izz="0.025767" />
    </inertial>
    <visual>
      <origin
        xyz="0 0 0"
        rpy="0 0 0" />
      <geometry>
        <mesh
          filename="meshes/wheel4.STL" />
      </geometry>
      <material
        name="">
        <color
          rgba="1 1 1 1" />
      </material>
    </visual>
    <collision>
      <origin
        xyz="0 0 0"
        rpy="0 0 0" />
      <surface>
        <friction>
          <ode>
            <mu>2.0</mu>
            <mu2>2.0</mu2>
          </ode>
        </friction>
      </surface>
      <geometry>
        <mesh
          filename="meshes/wheel4.STL" />
      </geometry>
    </collision>
  </link>
  <joint
    name="joint4"
    type="revolute">
    <origin
      xyz="-0.361 -0.56 0.14"
      rpy="1.5708 0 -1.5708" />
    <parent
      link="base_link" />
    <child
      link="wheel4" />
    <axis
      xyz="0 0 1" />
    <limit
      lower="-1.79769e+308"
      upper="1.79769e+308" 
      effort="10"
      velocity="10"/>
  </joint>
  <!-- Steering Joints (front wheels) -->
  <!-- <joint name="joint2" type="revolute">
    <origin xyz="0.361 0.56 0.14" rpy="-1.5708 0 -1.5708" />
    <parent link="base_link" />
    <child link="wheel2" />
    <axis xyz="0 1 0"/>
    <limit lower="-1.57" upper="1.57" effort="10" velocity="10" />
  </joint>
  <joint name="joint3" type="revolute">
    <origin xyz="-0.361 0.56 0.14" rpy="1.5708 0 -1.5708" />
    <parent link="base_link" />
    <child link="wheel3" />
    <axis xyz="0 -1 0"/>
    <limit lower="-1.57" upper="1.57" effort="10" velocity="10" />
  </joint> -->
 
  <gazebo xmlns:gz="https://ignitionrobotics.org">
    <plugin name="gz::sim::systems::DiffDrive" filename="libgz-sim-diff-drive-system.so">
      <left_joint>joint4</left_joint>
      <!-- <left_joint>joint3</left_joint> -->
      <right_joint>joint1</right_joint>
      <!-- <right_joint>joint2</right_joint> -->
      <wheel_separation>0.722</wheel_separation>
      <wheel_radius>0.14</wheel_radius>
      <odom_publish_frequency>1</odom_publish_frequency>
      <topic>/cmd_vel</topic>
      <debug>true</debug>
    </plugin>
  </gazebo>
  
 <!-- Ackermann Steering Plugin -->
  <!-- <gazebo xmlns:gz="https://ignitionrobotics.org">
    <plugin name="gz::sim::systems::AckermannSteering" filename="libgz-sim8-ackermann-steering-system.so">
      <steering_left_joint>joint3</steering_left_joint>
      <steering_right_joint>joint2</steering_right_joint>
      <left_wheel_joint>joint4</left_wheel_joint>
      <right_wheel_joint>joint1</right_wheel_joint>
      <wheel_separation>0.722</wheel_separation>
      <wheel_radius>0.14</wheel_radius>
      <wheel_base>1.12</wheel_base>  Adjust as per your robot's dimensions
      <steering_topic>/cmd_steering</steering_topic>
      <use_ackermann>true</use_ackermann>
    </plugin>
  </gazebo> -->
</robot>