<?xml version="1.0" encoding="utf-8"?>
<!-- This URDF was automatically created by SolidWorks to URDF Exporter! Originally created by Stephen Brawner (brawner@gmail.com) 
     Commit Version: 1.6.0-4-g7f85cfe  Build Version: 1.6.7995.38578
     For more information, please see http://wiki.ros.org/sw_urdf_exporter -->
     <!-- xyz="-6.9389E-18 0.012359 1.3957E-18" -->
<robot
  name="Car_Bot">
  <link
    name="CAR_BODY">
    <inertial>
      <origin  
        xyz="-6.9389E-18 0.012359 1.3957E-18"
        rpy="0 0 0" />
      <mass
        value="0.06661" />
      <inertia
        ixx="1.2286E-05"
        ixy="-2.3375E-21"
        ixz="4.7984E-22"
        iyy="3.2578E-05"
        iyz="-9.369E-22"
        izz="2.8742E-05" />
    </inertial>
    <visual>
      <origin
        xyz="0 0 0"
        rpy="0 0 0" />
      <geometry>
        <mesh filename="meshes/CAR_BODY.stl"/>
      </geometry>
      <material
        name="">
        <color
          rgba="0.79216 0.81961 0.93333 1" />
      </material>
    </visual>
    <collision>
      <origin
        xyz="0 0 0"
        rpy="0 0 0" />
      <geometry>
        <mesh filename="meshes/CAR_BODY.stl"/>
      </geometry>
    </collision>
  </link>
  <link
    name="wheel1">
    <inertial>
      <origin
        xyz="0.028 8.0569E-19 -0.018969"
        rpy="0 0 0" />
      <mass
        value="0.0002595" />
      <inertia
        ixx="4.2293E-09"
        ixy="-2.0357E-24"
        ixz="2.073E-25"
        iyy="4.2293E-09"
        iyz="-6.1302E-25"
        izz="8.0995E-09" />
    </inertial>
    <visual>
      <origin
        xyz="0 0 0"
        rpy="0 0 0" />
      <geometry>
        <mesh filename="meshes/wheel1.STL"/>
      </geometry>
      <material
        name="">
        <color
          rgba="0.79216 0.81961 0.93333 1" />
      </material>
    </visual>
    <collision>
      <origin
        xyz="0 0 0"
        rpy="0 0 0" />
      <geometry>
        <mesh filename="meshes/wheel1.STL"/>
      </geometry>
    </collision>
  </link>
  <joint
    name="joint1"
    type="revolute">
    <origin
      xyz="0 0 0"
      rpy="0 0 0" />
    <parent
      link="CAR_BODY" />
    <child
      link="wheel1" />
    <axis
      xyz="0 0 -1" />
    <limit
      lower="-1.79769e+308"
      upper="1.79769e+308"/>
  </joint>
  <link
    name="wheel2">
    <inertial>
      <origin
        xyz="-0.028 8.1367E-19 -0.018969"
        rpy="0 0 0" />
      <mass
        value="0.0002595" />
      <inertia
        ixx="4.2293E-09"
        ixy="-7.5057E-25"
        ixz="4.9881E-25"
        iyy="4.2293E-09"
        iyz="8.4438E-25"
        izz="8.0995E-09" />
    </inertial>
    <visual>
      <origin
        xyz="0 0 0"
        rpy="0 0 0" />
      <geometry>
        <mesh filename="meshes/wheel2.STL"/>
      </geometry>
      <material
        name="">
        <color
          rgba="0.79216 0.81961 0.93333 1" />
      </material>
    </visual>
    <collision>
      <origin
        xyz="0 0 0"
        rpy="0 0 0" />
      <geometry>
        <mesh filename="meshes/wheel2.STL"/>
      </geometry>
    </collision>
  </link>
  <joint
    name="joint2"
    type="revolute">
    <origin
      xyz="0 0 0"
      rpy="0 0 0" />
    <parent
      link="CAR_BODY" />
    <child
      link="wheel2" />
    <axis
      xyz="0 0 -1" />
    <limit
      lower="-1.79769e+308"
      upper="1.79769e+308"/>
  </joint>
  <link
    name="wheel3">
    <inertial>
      <origin
        xyz="-0.028 -3.6481E-18 0.018969"
        rpy="0 0 0" />
      <mass
        value="0.0002595" />
      <inertia
        ixx="4.2293E-09"
        ixy="-1.1469E-24"
        ixz="1.5806E-25"
        iyy="4.2293E-09"
        iyz="-7.7254E-25"
        izz="8.0995E-09" />
    </inertial>
    <visual>
      <origin
        xyz="0 0 0"
        rpy="0 0 0" />
      <geometry>
        <mesh filename="meshes/wheel3.STL"/>
      </geometry>
      <material
        name="">
        <color
          rgba="0.79216 0.81961 0.93333 1" />
      </material>
    </visual>
    <collision>
      <origin
        xyz="0 0 0"
        rpy="0 0 0" />
      <geometry>
        <mesh filename="meshes/wheel3.STL"/>
      </geometry>
    </collision>
  </link>
  <joint
    name="joint3"
    type="revolute">
    <origin
      xyz="0 0 0"
      rpy="0 0 0" />
    <parent
      link="CAR_BODY" />
    <child
      link="wheel3" />
    <axis
      xyz="0 0 1" />
    <limit
      lower="-1.79769e+308"
      upper="1.79769e+308"/>
  </joint>
  <link
    name="wheel4">
    <inertial>
      <origin
        xyz="0.028 -2.7406E-18 0.018969"
        rpy="0 0 0" />
      <mass
        value="0.0002595" />
      <inertia
        ixx="4.2293E-09"
        ixy="-2.4119E-24"
        ixz="2.3969E-26"
        iyy="4.2293E-09"
        iyz="4.0848E-25"
        izz="8.0995E-09" />
    </inertial>
    <visual>
      <origin
        xyz="0 0 0"
        rpy="0 0 0" />
      <geometry>
        <mesh filename="meshes/wheel4.STL"/>
      </geometry>
      <material
        name="">
        <color
          rgba="0.79216 0.81961 0.93333 1" />
      </material>
    </visual>
    <collision>
      <origin
        xyz="0 0 0"
        rpy="0 0 0" />
      <geometry>
        <mesh filename="meshes/wheel4.STL"/>
      </geometry>
    </collision>
  </link>
  <joint
    name="joint4"
    type="revolute">
    <origin
      xyz="0 0 0"
      rpy="0 0 0" />
    <parent
      link="CAR_BODY" />
    <child
      link="wheel4" />
    <axis
      xyz="0 0 1" />
    <limit
      lower="-1.79769e+308"
      upper="1.79769e+308"/>
  </joint>
</robot>